<?xml version="1.0" encoding="utf-8"?>
<!-- This URDF was automatically created by SolidWorks to URDF Exporter! Originally created by Stephen Brawner (brawner@gmail.com) 
     Commit Version: 1.5.0-0-g9aa0fdb  Build Version: 1.5.7004.21443
     For more information, please see http://wiki.ros.org/sw_urdf_exporter -->
<robot
  name="robot-description-baller">
  <link
    name="base_link">
    <inertial>
      <origin
        xyz="0.0578219058733361 -0.229051229490053 0.287494731522033"
        rpy="0 0 0" />
      <mass
        value="6.90496170242358" />
      <inertia
        ixx="0.0618638617883216"
        ixy="-4.86025906903307E-07"
        ixz="0.000933964995421894"
        iyy="0.0558956711612322"
        iyz="-5.9876445340078E-07"
        izz="0.0408835258693231" />
    </inertial>
    <visual>
      <origin
        xyz="0 0 0"
        rpy="0 0 0" />
      <geometry>
        <mesh
          filename="package://robot-description-baller/meshes/base_link.STL" />
      </geometry>
      <material
        name="">
        <color
          rgba="0.792156862745098 0.819607843137255 0.933333333333333 1" />
      </material>
    </visual>
    <collision>
      <origin
        xyz="0 0 0"
        rpy="0 0 0" />
      <geometry>
        <mesh
          filename="package://robot-description-baller/meshes/base_link.STL" />
      </geometry>
    </collision>
  </link>
  <link
    name="left_inner_rear_track_link">
    <inertial>
      <origin
        xyz="-0.348367785887154 -0.0274550398974908 -0.000219496335036373"
        rpy="0 0 0" />
      <mass
        value="4.17528833969494" />
      <inertia
        ixx="0.0207171956616369"
        ixy="1.33117978017255E-07"
        ixz="-1.92512775105517E-12"
        iyy="0.0207154450724253"
        iyz="2.5482459976023E-11"
        izz="0.0356331254802435" />
    </inertial>
    <visual>
      <origin
        xyz="0 0 0"
        rpy="0 0 0" />
      <geometry>
        <mesh
          filename="package://robot-description-baller/meshes/left_inner_rear_track_link.STL" />
      </geometry>
      <material
        name="">
        <color
          rgba="0.792156862745098 0.819607843137255 0.933333333333333 1" />
      </material>
    </visual>
    <collision>
      <origin
        xyz="0 0 0"
        rpy="0 0 0" />
      <geometry>
        <mesh
          filename="package://robot-description-baller/meshes/left_inner_rear_track_link.STL" />
      </geometry>
    </collision>
  </link>
  <joint
    name="left_inner_rear_track_joint"
    type="revolute">
    <origin
      xyz="0.40808 -0.068572 0.27695"
      rpy="1.5708 0.031025 0" />
    <parent
      link="base_link" />
    <child
      link="left_inner_rear_track_link" />
    <axis
      xyz="0 0 0" />
    <limit
      lower="0"
      upper="0"
      effort="0"
      velocity="0" />
    <safety_controller
      k_velocity="0" />
  </joint>
  <link
    name="left_inner_track_base_link">
    <inertial>
      <origin
        xyz="0.208894785796513 -0.0146887943523822 -0.00134460830658914"
        rpy="0 0 0" />
      <mass
        value="2.20888146035223" />
      <inertia
        ixx="0.0177115705958669"
        ixy="-0.000442907878950439"
        ixz="-1.97853121902233E-06"
        iyy="0.0230391356369313"
        iyz="-1.34748584330851E-05"
        izz="0.0385405863901358" />
    </inertial>
    <visual>
      <origin
        xyz="0 0 0"
        rpy="0 0 0" />
      <geometry>
        <mesh
          filename="package://robot-description-baller/meshes/left_inner_track_base_link.STL" />
      </geometry>
      <material
        name="">
        <color
          rgba="0.792156862745098 0.819607843137255 0.933333333333333 1" />
      </material>
    </visual>
    <collision>
      <origin
        xyz="0 0 0"
        rpy="0 0 0" />
      <geometry>
        <mesh
          filename="package://robot-description-baller/meshes/left_inner_track_base_link.STL" />
      </geometry>
    </collision>
  </link>
  <joint
    name="left_inner_track_base_joint"
    type="fixed">
    <origin
      xyz="-0.38203 0.0023495 0.0065379"
      rpy="0 0 0" />
    <parent
      link="left_inner_rear_track_link" />
    <child
      link="left_inner_track_base_link" />
    <axis
      xyz="0 0 0" />
    <safety_controller
      k_velocity="0" />
  </joint>
  <link
    name="left_inner_front_track_link">
    <inertial>
      <origin
        xyz="0.000219496328952254 0.00135538170549637 -0.000450797126796576"
        rpy="0 0 0" />
      <mass
        value="4.17528833969495" />
      <inertia
        ixx="0.0356331254802435"
        ixy="2.5466367458297E-11"
        ixz="-1.99314228100425E-10"
        iyy="0.020715446990881"
        iyz="-1.45172805605886E-07"
        izz="0.0207171937431812" />
    </inertial>
    <visual>
      <origin
        xyz="0 0 0"
        rpy="0 0 0" />
      <geometry>
        <mesh
          filename="package://robot-description-baller/meshes/left_inner_front_track_link.STL" />
      </geometry>
      <material
        name="">
        <color
          rgba="0.792156862745098 0.819607843137255 0.933333333333333 1" />
      </material>
    </visual>
    <collision>
      <origin
        xyz="0 0 0"
        rpy="0 0 0" />
      <geometry>
        <mesh
          filename="package://robot-description-baller/meshes/left_inner_front_track_link.STL" />
      </geometry>
    </collision>
  </link>
  <joint
    name="left_inner_front_track_joint"
    type="revolute">
    <origin
      xyz="0.38203 -0.0023495 -0.0065379"
      rpy="3.1416 -1.5708 -3.1368" />
    <parent
      link="left_inner_track_base_link" />
    <child
      link="left_inner_front_track_link" />
    <axis
      xyz="0 0 0" />
    <limit
      lower="0"
      upper="0"
      effort="0"
      velocity="0" />
    <safety_controller
      k_velocity="0" />
  </joint>
  <link
    name="left_outer_track_front_link">
    <inertial>
      <origin
        xyz="0.000219496335155479 1.94725701902487E-05 0.000441797714475001"
        rpy="0 0 0" />
      <mass
        value="4.17528833969495" />
      <inertia
        ixx="0.0356331254802435"
        ixy="-1.94735109800564E-10"
        ixz="3.64298498652816E-12"
        iyy="0.0207154470244562"
        iyz="1.45374653749959E-07"
        izz="0.0207171937096059" />
    </inertial>
    <visual>
      <origin
        xyz="0 0 0"
        rpy="0 0 0" />
      <geometry>
        <mesh
          filename="package://robot-description-baller/meshes/left_outer_track_front_link.STL" />
      </geometry>
      <material
        name="">
        <color
          rgba="0.792156862745098 0.819607843137255 0.933333333333333 1" />
      </material>
    </visual>
    <collision>
      <origin
        xyz="0 0 0"
        rpy="0 0 0" />
      <geometry>
        <mesh
          filename="package://robot-description-baller/meshes/left_outer_track_front_link.STL" />
      </geometry>
    </collision>
  </link>
  <joint
    name="left_outer_track_front_joint"
    type="revolute">
    <origin
      xyz="-0.10172 0.0013359 0"
      rpy="3.1416 0 3.1416" />
    <parent
      link="left_inner_front_track_link" />
    <child
      link="left_outer_track_front_link" />
    <axis
      xyz="0 0 0" />
    <limit
      lower="0"
      upper="0"
      effort="0"
      velocity="0" />
    <safety_controller
      k_velocity="0" />
  </joint>
  <link
    name="left_out_track_base_link">
    <inertial>
      <origin
        xyz="0.208955891820383 -0.0154395863840132 -0.00134460830658937"
        rpy="0 0 0" />
      <mass
        value="2.20888146035223" />
      <inertia
        ixx="0.0177155549696435"
        ixy="-0.000466238698999306"
        ixz="-1.91945864226303E-06"
        iyy="0.0230351512631547"
        iyz="-1.34833999457476E-05"
        izz="0.0385405863901358" />
    </inertial>
    <visual>
      <origin
        xyz="0 0 0"
        rpy="0 0 0" />
      <geometry>
        <mesh
          filename="package://robot-description-baller/meshes/left_out_track_base_link.STL" />
      </geometry>
      <material
        name="">
        <color
          rgba="0.792156862745098 0.819607843137255 0.933333333333333 1" />
      </material>
    </visual>
    <collision>
      <origin
        xyz="0 0 0"
        rpy="0 0 0" />
      <geometry>
        <mesh
          filename="package://robot-description-baller/meshes/left_out_track_base_link.STL" />
      </geometry>
    </collision>
  </link>
  <joint
    name="left_out_track_base_joint"
    type="fixed">
    <origin
      xyz="-0.0065379 0.011325 -0.38187"
      rpy="1.5708 -1.5438 -1.5708" />
    <parent
      link="left_outer_track_front_link" />
    <child
      link="left_out_track_base_link" />
    <axis
      xyz="0 0 0" />
    <safety_controller
      k_velocity="0" />
  </joint>
  <link
    name="left_outer_track_rear_link">
    <inertial>
      <origin
        xyz="-0.103779813958259 -0.0338202975658785 0.34783114382747"
        rpy="0 0 0" />
      <mass
        value="4.50966940783013" />
      <inertia
        ixx="0.0357811712676882"
        ixy="2.21243990172557E-10"
        ixz="-2.7473965138921E-09"
        iyy="0.0215005422044002"
        iyz="-1.18860702397074E-07"
        izz="0.0215020841314735" />
    </inertial>
    <visual>
      <origin
        xyz="0 0 0"
        rpy="0 0 0" />
      <geometry>
        <mesh
          filename="package://robot-description-baller/meshes/left_outer_track_rear_link.STL" />
      </geometry>
      <material
        name="">
        <color
          rgba="0.792156862745098 0.819607843137255 0.933333333333333 1" />
      </material>
    </visual>
    <collision>
      <origin
        xyz="0 0 0"
        rpy="0 0 0" />
      <geometry>
        <mesh
          filename="package://robot-description-baller/meshes/left_outer_track_rear_link.STL" />
      </geometry>
    </collision>
  </link>
  <joint
    name="left_outer_track_rear_joint"
    type="revolute">
    <origin
      xyz="0.38206 -0.0023492 0.095182"
      rpy="3.1277 -1.5708 0" />
    <parent
      link="left_out_track_base_link" />
    <child
      link="left_outer_track_rear_link" />
    <axis
      xyz="0 0 0" />
    <limit
      lower="0"
      upper="0"
      effort="0"
      velocity="0" />
    <safety_controller
      k_velocity="0" />
  </joint>
  <link
    name="right_inner_track_link">
    <inertial>
      <origin
        xyz="0.000219496335037872 -0.028834803460506 0.000360925352606178"
        rpy="0 0 0" />
      <mass
        value="4.17528833969495" />
      <inertia
        ixx="0.0356331254802435"
        ixy="-2.55545716835766E-11"
        ixz="-1.62224634006936E-13"
        iyy="0.020715435077784"
        iyz="-1.11351693239323E-08"
        izz="0.0207172056562782" />
    </inertial>
    <visual>
      <origin
        xyz="0 0 0"
        rpy="0 0 0" />
      <geometry>
        <mesh
          filename="package://robot-description-baller/meshes/right_inner_track_link.STL" />
      </geometry>
      <material
        name="">
        <color
          rgba="0.792156862745098 0.819607843137255 0.933333333333333 1" />
      </material>
    </visual>
    <collision>
      <origin
        xyz="0 0 0"
        rpy="0 0 0" />
      <geometry>
        <mesh
          filename="package://robot-description-baller/meshes/right_inner_track_link.STL" />
      </geometry>
    </collision>
  </link>
  <joint
    name="right_inner_track_joint"
    type="revolute">
    <origin
      xyz="0.058294 -0.38953 0.28914"
      rpy="1.6088 0 -1.5708" />
    <parent
      link="base_link" />
    <child
      link="right_inner_track_link" />
    <axis
      xyz="0 0 0" />
    <limit
      lower="0"
      upper="0"
      effort="0"
      velocity="0" />
    <safety_controller
      k_velocity="0" />
  </joint>
  <link
    name="right_inner_track_base_link">
    <inertial>
      <origin
        xyz="0.176421252755492 -0.0136968698089939 -0.00480669220342167"
        rpy="0 0 0" />
      <mass
        value="2.20888146035223" />
      <inertia
        ixx="0.0177115705958669"
        ixy="-0.000442907878950379"
        ixz="-1.97853121899421E-06"
        iyy="0.0230391356369314"
        iyz="-1.34748584330889E-05"
        izz="0.0385405863901358" />
    </inertial>
    <visual>
      <origin
        xyz="0 0 0"
        rpy="0 0 0" />
      <geometry>
        <mesh
          filename="package://robot-description-baller/meshes/right_inner_track_base_link.STL" />
      </geometry>
      <material
        name="">
        <color
          rgba="0.792156862745098 0.819607843137255 0.933333333333333 1" />
      </material>
    </visual>
    <collision>
      <origin
        xyz="0 0 0"
        rpy="0 0 0" />
      <geometry>
        <mesh
          filename="package://robot-description-baller/meshes/right_inner_track_base_link.STL" />
      </geometry>
    </collision>
  </link>
  <joint
    name="right_inner_track_base_joint"
    type="fixed">
    <origin
      xyz="0.01 0 0"
      rpy="-1.5708 1.5171 -1.5708" />
    <parent
      link="right_inner_track_link" />
    <child
      link="right_inner_track_base_link" />
    <axis
      xyz="0 0 0" />
    <safety_controller
      k_velocity="0" />
  </joint>
  <link
    name="right_inner_track_front_link">
    <inertial>
      <origin
        xyz="0.000219496335038094 3.99930089045597E-12 6.43929354282591E-15"
        rpy="0 0 0" />
      <mass
        value="4.17528833969495" />
      <inertia
        ixx="0.0356331254802435"
        ixy="1.43629860785195E-10"
        ixz="5.95294617372261E-12"
        iyy="0.0207154383281579"
        iyz="7.66059342907276E-08"
        izz="0.0207172024059043" />
    </inertial>
    <visual>
      <origin
        xyz="0 0 0"
        rpy="0 0 0" />
      <geometry>
        <mesh
          filename="package://robot-description-baller/meshes/right_inner_track_front_link.STL" />
      </geometry>
      <material
        name="">
        <color
          rgba="0.792156862745098 0.819607843137255 0.933333333333333 1" />
      </material>
    </visual>
    <collision>
      <origin
        xyz="0 0 0"
        rpy="0 0 0" />
      <geometry>
        <mesh
          filename="package://robot-description-baller/meshes/right_inner_track_front_link.STL" />
      </geometry>
    </collision>
  </link>
  <joint
    name="right_inner_track_front_joint"
    type="revolute">
    <origin
      xyz="0.35 0 -0.01"
      rpy="0.045111 1.5708 0" />
    <parent
      link="right_inner_track_base_link" />
    <child
      link="right_inner_track_front_link" />
    <axis
      xyz="0 0 0" />
    <limit
      lower="0"
      upper="0"
      effort="0"
      velocity="0" />
    <safety_controller
      k_velocity="0" />
  </joint>
  <link
    name="right_outer_track_front_link">
    <inertial>
      <origin
        xyz="-3.09096026551714E-09 -0.0533139967701026 3.74369119593432E-08"
        rpy="0 0 0" />
      <mass
        value="4.50966940783014" />
      <inertia
        ixx="0.0214124543703475"
        ixy="5.43472898690916E-10"
        ixz="-1.27896829473485E-07"
        iyy="0.0357811712676883"
        iyz="-6.26883758973374E-09"
        izz="0.021413993402566" />
    </inertial>
    <visual>
      <origin
        xyz="0 0 0"
        rpy="0 0 0" />
      <geometry>
        <mesh
          filename="package://robot-description-baller/meshes/right_outer_track_front_link.STL" />
      </geometry>
      <material
        name="">
        <color
          rgba="0.792156862745098 0.819607843137255 0.933333333333333 1" />
      </material>
    </visual>
    <collision>
      <origin
        xyz="0 0 0"
        rpy="0 0 0" />
      <geometry>
        <mesh
          filename="package://robot-description-baller/meshes/right_outer_track_front_link.STL" />
      </geometry>
    </collision>
  </link>
  <joint
    name="right_outer_track_front_joint"
    type="revolute">
    <origin
      xyz="-0.04672 0 0"
      rpy="0 -1.5316 -1.5708" />
    <parent
      link="right_inner_track_front_link" />
    <child
      link="right_outer_track_front_link" />
    <axis
      xyz="0 0 0" />
    <limit
      lower="0"
      upper="0"
      effort="0"
      velocity="0" />
    <safety_controller
      k_velocity="0" />
  </joint>
  <link
    name="right_outer_track_base_link">
    <inertial>
      <origin
        xyz="0.207914697106206 -0.000374618691388662 -0.0013446083065895"
        rpy="0 0 0" />
      <mass
        value="2.20888146035223" />
      <inertia
        ixx="0.0176750004221534"
        ixy="1.8058094778415E-07"
        ixz="-3.08108847310618E-06"
        iyy="0.0230757058106448"
        iyz="-1.32662462436482E-05"
        izz="0.0385405863901358" />
    </inertial>
    <visual>
      <origin
        xyz="0 0 0"
        rpy="0 0 0" />
      <geometry>
        <mesh
          filename="package://robot-description-baller/meshes/right_outer_track_base_link.STL" />
      </geometry>
      <material
        name="">
        <color
          rgba="0.792156862745098 0.819607843137255 0.933333333333333 1" />
      </material>
    </visual>
    <collision>
      <origin
        xyz="0 0 0"
        rpy="0 0 0" />
      <geometry>
        <mesh
          filename="package://robot-description-baller/meshes/right_outer_track_base_link.STL" />
      </geometry>
    </collision>
  </link>
  <joint
    name="right_outer_track_base_joint"
    type="fixed">
    <origin
      xyz="-0.38202 -0.061538 -0.0027053"
      rpy="1.5708 -0.0097345 0" />
    <parent
      link="right_outer_track_front_link" />
    <child
      link="right_outer_track_base_link" />
    <axis
      xyz="0 0 0" />
    <safety_controller
      k_velocity="0" />
  </joint>
  <link
    name="right_outer_rear_track_joint">
    <inertial>
      <origin
        xyz="-0.00205981876088124 -0.00999999358462084 -3.70124209614353E-08"
        rpy="0 0 0" />
      <mass
        value="4.50966940783013" />
      <inertia
        ixx="0.0357811712676882"
        ixy="4.62441936247664E-10"
        ixz="-2.5177019544376E-09"
        iyy="0.0215005785858569"
        iyz="-2.62491541323925E-07"
        izz="0.0215020477500167" />
    </inertial>
    <visual>
      <origin
        xyz="0 0 0"
        rpy="0 0 0" />
      <geometry>
        <mesh
          filename="package://robot-description-baller/meshes/right_outer_rear_track_joint.STL" />
      </geometry>
      <material
        name="">
        <color
          rgba="0.792156862745098 0.819607843137255 0.933333333333333 1" />
      </material>
    </visual>
    <collision>
      <origin
        xyz="0 0 0"
        rpy="0 0 0" />
      <geometry>
        <mesh
          filename="package://robot-description-baller/meshes/right_outer_rear_track_joint.STL" />
      </geometry>
    </collision>
  </link>
  <joint
    name="right_outer_rear_track_joint"
    type="continuous">
    <origin
      xyz="0.033221 -0.010943 -0.0065379"
      rpy="3.0224 1.5708 0" />
    <parent
      link="right_outer_track_base_link" />
    <child
      link="right_outer_rear_track_joint" />
    <axis
      xyz="0 0 0" />
    <safety_controller
      k_velocity="0" />
  </joint>
  <link
    name="torso_upper_link">
    <inertial>
      <origin
        xyz="-0.00138612726783582 0.00772682731357199 -0.0238262385746277"
        rpy="0 0 0" />
      <mass
        value="10.7560323516289" />
      <inertia
        ixx="0.126724222632888"
        ixy="0.000236382801053609"
        ixz="-2.66894549877839E-05"
        iyy="0.0661744477193023"
        iyz="0.00771959988498224"
        izz="0.155042665551656" />
    </inertial>
    <visual>
      <origin
        xyz="0 0 0"
        rpy="0 0 0" />
      <geometry>
        <mesh
          filename="package://robot-description-baller/meshes/torso_upper_link.STL" />
      </geometry>
      <material
        name="">
        <color
          rgba="0.792156862745098 0.819607843137255 0.933333333333333 1" />
      </material>
    </visual>
    <collision>
      <origin
        xyz="0 0 0"
        rpy="0 0 0" />
      <geometry>
        <mesh
          filename="package://robot-description-baller/meshes/torso_upper_link.STL" />
      </geometry>
    </collision>
  </link>
  <joint
    name="torso_upper_joint"
    type="fixed">
    <origin
      xyz="0.0664223731950749 -0.228813198152485 0.63873329880116"
      rpy="1.60879007547593 0.00175498333508944 1.52465997053619" />
    <parent
      link="base_link" />
    <child
      link="torso_upper_link" />
    <axis
      xyz="0 0 0" />
    <safety_controller
      k_velocity="0" />
  </joint>
</robot>