<?xml version="1.0" encoding="utf-8"?>
<!-- This URDF was automatically created by SolidWorks to URDF Exporter! Originally created by Stephen Brawner (brawner@gmail.com) 
     Commit Version: 1.5.0-0-g9aa0fdb  Build Version: 1.5.7004.21443
     For more information, please see http://wiki.ros.org/sw_urdf_exporter -->
<robot
  name="robot-description-irvin">
    <gazebo>
    <plugin filename="libgazebo_ros_diff_drive.so" name="differential_drive_controller">
      <alwaysOn>true</alwaysOn>
      <updateRate>20</updateRate>
      <leftJoint>left_outer_track_rear_joint</leftJoint>
      <rightJoint>right_outer_rear_track_joint</rightJoint>
      <wheelSeparation>0.5207</wheelSeparation>
      <wheelDiameter>0.0381</wheelDiameter>
      <torque>0.1</torque>
      <commandTopic>cmd_vel</commandTopic>
      <odometryTopic>odom</odometryTopic>
      <odometryFrame>odom</odometryFrame>
      <robotBaseFrame>base_link</robotBaseFrame>
      <legacyMode>false</legacyMode>
    </plugin>
  </gazebo>
  <link
    name="base_link">
    <inertial>
      <origin
        xyz="0.0593277196241563 -0.229051233143237 0.316329557872373"
        rpy="0 0 0" />
      <mass
        value="6.90496213213785" />
      <inertia
        ixx="0.0618749358211769"
        ixy="-5.30670580740332E-07"
        ixz="-0.000799972791594144"
        iyy="0.0558956803247678"
        iyz="-5.54041887308258E-07"
        izz="0.0408724634072406" />
    </inertial>
    <visual>
      <origin
        xyz="0 0 0"
        rpy="0 0 0" />
      <geometry>
        <mesh
          filename="package://robot-description-irvin/meshes/base_link.STL" />
      </geometry>
      <material
        name="">
        <color
          rgba="0.792156862745098 0.819607843137255 0.933333333333333 1" />
      </material>
    </visual>
    <collision>
      <origin
        xyz="0 0 0"
        rpy="0 0 0" />
      <geometry>
        <mesh
          filename="package://robot-description-irvin/meshes/base_link.STL" />
      </geometry>
    </collision>
  </link>
  <link
    name="left_inner_rear_track_link">
    <inertial>
      <origin
        xyz="-0.35 0.0013359 -0.0002195"
        rpy="0 0 0" />
      <mass
        value="4.1753" />
      <inertia
        ixx="0.020717"
        ixy="-1.2309E-08"
        ixz="1.7916E-13"
        iyy="0.020715"
        iyz="2.5554E-11"
        izz="0.035633" />
    </inertial>
    <visual>
      <origin
        xyz="0 0 0"
        rpy="0 0 0" />
      <geometry>
        <mesh
          filename="package://robot-description-irvin/meshes/left_inner_rear_track_link.STL" />
      </geometry>
      <material
        name="">
        <color
          rgba="0.79216 0.81961 0.93333 1" />
      </material>
    </visual>
    <collision>
      <origin
        xyz="0 0 0"
        rpy="0 0 0" />
      <geometry>
        <mesh
          filename="package://robot-description-irvin/meshes/left_inner_rear_track_link.STL" />
      </geometry>
    </collision>
  </link>
  <joint
    name="left_inner_rear_track_joint"
    type="revolute">
    <origin
      xyz="0.40808 -0.068572 0.27695"
      rpy="1.5708 0.031025 0" />
    <parent
      link="base_link" />
    <child
      link="left_inner_rear_track_link" />
    <axis
      xyz="0 0 0" />
    <limit
      lower="0"
      upper="0"
      effort="0"
      velocity="0" />
    <safety_controller
      k_velocity="0" />
  </joint>
  <link
    name="left_inner_track_base_link">
    <inertial>
      <origin
        xyz="0.207914697106206 -0.00037461869138905 -0.00134460830658915"
        rpy="0 0 0" />
      <mass
        value="2.20888146035223" />
      <inertia
        ixx="0.0176750004221534"
        ixy="1.80580947801924E-07"
        ixz="-3.08108847310402E-06"
        iyy="0.0230757058106448"
        iyz="-1.32662462436398E-05"
        izz="0.0385405863901358" />
    </inertial>
    <visual>
      <origin
        xyz="0 0 0"
        rpy="0 0 0" />
      <geometry>
        <mesh
          filename="package://robot-description-irvin/meshes/left_inner_track_base_link.STL" />
      </geometry>
      <material
        name="">
        <color
          rgba="0.792156862745098 0.819607843137255 0.933333333333333 1" />
      </material>
    </visual>
    <collision>
      <origin
        xyz="0 0 0"
        rpy="0 0 0" />
      <geometry>
        <mesh
          filename="package://robot-description-irvin/meshes/left_inner_track_base_link.STL" />
      </geometry>
    </collision>
  </link>
  <joint
    name="left_inner_track_base_joint"
    type="fixed">
    <origin
      xyz="-0.38203 0.0023495 0.0065379"
      rpy="0 0 0" />
    <parent
      link="left_inner_rear_track_link" />
    <child
      link="left_inner_track_base_link" />
    <axis
      xyz="0 0 0" />
    <safety_controller
      k_velocity="0" />
  </joint>
  <link
    name="left_inner_front_track_link">
    <inertial>
      <origin
        xyz="0.000219496334918079 0.00133590913055326 -8.99941240734004E-06"
        rpy="0 0 0" />
      <mass
        value="4.17528833969494" />
      <inertia
        ixx="0.0356331254802435"
        ixy="2.55550739996529E-11"
        ixz="-2.01417804650358E-10"
        iyy="0.0207154350077636"
        iyz="1.02310762553862E-10"
        izz="0.0207172057262986" />
    </inertial>
    <visual>
      <origin
        xyz="0 0 0"
        rpy="0 0 0" />
      <geometry>
        <mesh
          filename="package://robot-description-irvin/meshes/left_inner_front_track_link.STL" />
      </geometry>
      <material
        name="">
        <color
          rgba="0.792156862745098 0.819607843137255 0.933333333333333 1" />
      </material>
    </visual>
    <collision>
      <origin
        xyz="0 0 0"
        rpy="0 0 0" />
      <geometry>
        <mesh
          filename="package://robot-description-irvin/meshes/left_inner_front_track_link.STL" />
      </geometry>
    </collision>
  </link>
  <joint
    name="left_inner_front_track_joint"
    type="revolute">
    <origin
      xyz="0.38203 -0.0023495 -0.0065379"
      rpy="3.1416 -1.5708 -3.1368" />
    <parent
      link="left_inner_track_base_link" />
    <child
      link="left_inner_front_track_link" />
    <axis
      xyz="0 0 0" />
    <limit
      lower="0"
      upper="0"
      effort="0"
      velocity="0" />
    <safety_controller
      k_velocity="0" />
  </joint>
  <link
    name="left_outer_track_front_link">
    <inertial>
      <origin
        xyz="0.000219496335038039 -4.75186556769813E-12 8.44879721739744E-14"
        rpy="0 0 0" />
      <mass
        value="4.17528833969494" />
      <inertia
        ixx="0.0356331254802435"
        ixy="-1.94648504078499E-10"
        ixz="5.74457396623407E-12"
        iyy="0.0207154350077636"
        iyz="1.02310762854013E-10"
        izz="0.0207172057262986" />
    </inertial>
    <visual>
      <origin
        xyz="0 0 0"
        rpy="0 0 0" />
      <geometry>
        <mesh
          filename="package://robot-description-irvin/meshes/left_outer_track_front_link.STL" />
      </geometry>
      <material
        name="">
        <color
          rgba="0.792156862745098 0.819607843137255 0.933333333333333 1" />
      </material>
    </visual>
    <collision>
      <origin
        xyz="0 0 0"
        rpy="0 0 0" />
      <geometry>
        <mesh
          filename="package://robot-description-irvin/meshes/left_outer_track_front_link.STL" />
      </geometry>
    </collision>
  </link>
  <joint
    name="left_outer_track_front_joint"
    type="revolute">
    <origin
      xyz="-0.10172 0.0013359 0"
      rpy="3.1416 0 3.1416" />
    <parent
      link="left_inner_front_track_link" />
    <child
      link="left_outer_track_front_link" />
    <axis
      xyz="0 0 0" />
    <limit
      lower="0"
      upper="0"
      effort="0"
      velocity="0" />
    <safety_controller
      k_velocity="0" />
  </joint>
  <link
    name="left_out_track_base_link">
    <inertial>
      <origin
        xyz="0.207914697106206 -0.000374618691388662 -0.00134460830658937"
        rpy="0 0 0" />
      <mass
        value="2.20888146035223" />
      <inertia
        ixx="0.0176750004221534"
        ixy="1.80580947832824E-07"
        ixz="-3.08108847311774E-06"
        iyy="0.0230757058106447"
        iyz="-1.32662462436444E-05"
        izz="0.0385405863901357" />
    </inertial>
    <visual>
      <origin
        xyz="0 0 0"
        rpy="0 0 0" />
      <geometry>
        <mesh
          filename="package://robot-description-irvin/meshes/left_out_track_base_link.STL" />
      </geometry>
      <material
        name="">
        <color
          rgba="0.792156862745098 0.819607843137255 0.933333333333333 1" />
      </material>
    </visual>
    <collision>
      <origin
        xyz="0 0 0"
        rpy="0 0 0" />
      <geometry>
        <mesh
          filename="package://robot-description-irvin/meshes/left_out_track_base_link.STL" />
      </geometry>
    </collision>
  </link>
  <joint
    name="left_out_track_base_joint"
    type="fixed">
    <origin
      xyz="-0.0065379 0.011325 -0.38187"
      rpy="1.5708 -1.5438 -1.5708" />
    <parent
      link="left_outer_track_front_link" />
    <child
      link="left_out_track_base_link" />
    <axis
      xyz="0 0 0" />
    <safety_controller
      k_velocity="0" />
  </joint>
  <link
    name="left_outer_track_rear_link">
    <inertial>
      <origin
        xyz="-0.103779813928151 -0.00353814246978357 0.3500116932782"
        rpy="0 0 0" />
      <mass
        value="4.50966940783013" />
      <inertia
        ixx="0.0357811712676882"
        ixy="2.55694481991313E-11"
        ixz="-2.75684776123974E-09"
        iyy="0.0215005330957408"
        iyz="1.02310762441461E-10"
        izz="0.0215020932401328" />
    </inertial>
    <visual>
      <origin
        xyz="0 0 0"
        rpy="0 0 0" />
      <geometry>
        <mesh
          filename="package://robot-description-irvin/meshes/left_outer_track_rear_link.STL" />
      </geometry>
      <material
        name="">
        <color
          rgba="0.792156862745098 0.819607843137255 0.933333333333333 1" />
      </material>
    </visual>
    <collision>
      <origin
        xyz="0 0 0"
        rpy="0 0 0" />
      <geometry>
        <mesh
          filename="package://robot-description-irvin/meshes/left_outer_track_rear_link.STL" />
      </geometry>
    </collision>
  </link>
  <joint
    name="left_outer_track_rear_joint"
    type="continuous">
    <origin
      xyz="0.38206 -0.0023492 0.095182"
      rpy="3.1277 -1.5708 0" />
    <parent
      link="left_out_track_base_link" />
    <child
      link="left_outer_track_rear_link" />
    <axis
      xyz="0 0 -1" />
    <safety_controller
      k_velocity="0" />
  </joint>
  <link
    name="right_inner_track_link">
    <inertial>
      <origin
        xyz="0.000219496335037983 1.50746082283604E-12 -1.14824816321857E-13"
        rpy="0 0 0" />
      <mass
        value="4.17528833969495" />
      <inertia
        ixx="0.0356331254802435"
        ixy="-2.54811794464166E-11"
        ixz="1.94202072045672E-12"
        iyy="0.0207154452496313"
        iyz="1.34277993979232E-07"
        izz="0.0207171954844308" />
    </inertial>
    <visual>
      <origin
        xyz="0 0 0"
        rpy="0 0 0" />
      <geometry>
        <mesh
          filename="package://robot-description-irvin/meshes/right_inner_track_link.STL" />
      </geometry>
      <material
        name="">
        <color
          rgba="0.792156862745098 0.819607843137255 0.933333333333333 1" />
      </material>
    </visual>
    <collision>
      <origin
        xyz="0 0 0"
        rpy="0 0 0" />
      <geometry>
        <mesh
          filename="package://robot-description-irvin/meshes/right_inner_track_link.STL" />
      </geometry>
    </collision>
  </link>
  <joint
    name="right_inner_track_joint"
    type="revolute">
    <origin
      xyz="0.058294 -0.38953 0.28914"
      rpy="1.6088 0 -1.5708" />
    <parent
      link="base_link" />
    <child
      link="right_inner_track_link" />
    <axis
      xyz="0 0 0" />
    <limit
      lower="0"
      upper="0"
      effort="0"
      velocity="0" />
    <safety_controller
      k_velocity="0" />
  </joint>
  <link
    name="right_inner_track_base_link">
    <inertial>
      <origin
        xyz="0.175882862618142 0.000638911171242873 -0.00480669220342189"
        rpy="0 0 0" />
      <mass
        value="2.20888146035223" />
      <inertia
        ixx="0.0176750004221534"
        ixy="1.80580947836863E-07"
        ixz="-3.08108847312725E-06"
        iyy="0.0230757058106447"
        iyz="-1.3266246243635E-05"
        izz="0.0385405863901357" />
    </inertial>
    <visual>
      <origin
        xyz="0 0 0"
        rpy="0 0 0" />
      <geometry>
        <mesh
          filename="package://robot-description-irvin/meshes/right_inner_track_base_link.STL" />
      </geometry>
      <material
        name="">
        <color
          rgba="0.792156862745098 0.819607843137255 0.933333333333333 1" />
      </material>
    </visual>
    <collision>
      <origin
        xyz="0 0 0"
        rpy="0 0 0" />
      <geometry>
        <mesh
          filename="package://robot-description-irvin/meshes/right_inner_track_base_link.STL" />
      </geometry>
    </collision>
  </link>
  <joint
    name="right_inner_track_base_joint"
    type="fixed">
    <origin
      xyz="0.01 0 0"
      rpy="-1.5708 1.5171 -1.5708" />
    <parent
      link="right_inner_track_link" />
    <child
      link="right_inner_track_base_link" />
    <axis
      xyz="0 0 0" />
    <safety_controller
      k_velocity="0" />
  </joint>
  <link
    name="right_inner_track_front_link">
    <inertial>
      <origin
        xyz="0.000219496335038039 3.99963395736336E-12 1.30506716544687E-13"
        rpy="0 0 0" />
      <mass
        value="4.17528833969495" />
      <inertia
        ixx="0.0356331254802435"
        ixy="1.43625593680623E-10"
        ixz="3.84908041827058E-12"
        iyy="0.0207154377132131"
        iyz="-6.91612649754836E-08"
        izz="0.0207172030208491" />
    </inertial>
    <visual>
      <origin
        xyz="0 0 0"
        rpy="0 0 0" />
      <geometry>
        <mesh
          filename="package://robot-description-irvin/meshes/right_inner_track_front_link.STL" />
      </geometry>
      <material
        name="">
        <color
          rgba="0.792156862745098 0.819607843137255 0.933333333333333 1" />
      </material>
    </visual>
    <collision>
      <origin
        xyz="0 0 0"
        rpy="0 0 0" />
      <geometry>
        <mesh
          filename="package://robot-description-irvin/meshes/right_inner_track_front_link.STL" />
      </geometry>
    </collision>
  </link>
  <joint
    name="right_inner_track_front_joint"
    type="revolute">
    <origin
      xyz="0.35 0 -0.01"
      rpy="0.045111 1.5708 0" />
    <parent
      link="right_inner_track_base_link" />
    <child
      link="right_inner_track_front_link" />
    <axis
      xyz="0 0 0" />
    <limit
      lower="0"
      upper="0"
      effort="0"
      velocity="0" />
    <safety_controller
      k_velocity="0" />
  </joint>
  <link
    name="right_outer_track_front_link">
    <inertial>
      <origin
        xyz="1.3996026559937E-12 -0.0533139967701027 3.75642966732315E-08"
        rpy="0 0 0" />
      <mass
        value="4.50966940783013" />
      <inertia
        ixx="0.0214124438142607"
        ixy="2.55670994315511E-11"
        ixz="1.02310770342924E-10"
        iyy="0.0357811712676882"
        iyz="-6.2922995653407E-09"
        izz="0.0214140039586526" />
    </inertial>
    <visual>
      <origin
        xyz="0 0 0"
        rpy="0 0 0" />
      <geometry>
        <mesh
          filename="package://robot-description-irvin/meshes/right_outer_track_front_link.STL" />
      </geometry>
      <material
        name="">
        <color
          rgba="0.792156862745098 0.819607843137255 0.933333333333333 1" />
      </material>
    </visual>
    <collision>
      <origin
        xyz="0 0 0"
        rpy="0 0 0" />
      <geometry>
        <mesh
          filename="package://robot-description-irvin/meshes/right_outer_track_front_link.STL" />
      </geometry>
    </collision>
  </link>
  <joint
    name="right_outer_track_front_joint"
    type="revolute">
    <origin
      xyz="-0.04672 0 0"
      rpy="0 -1.5316 -1.5708" />
    <parent
      link="right_inner_track_front_link" />
    <child
      link="right_outer_track_front_link" />
    <axis
      xyz="0 0 0" />
    <limit
      lower="0"
      upper="0"
      effort="0"
      velocity="0" />
    <safety_controller
      k_velocity="0" />
  </joint>
  <link
    name="right_outer_track_base_link">
    <inertial>
      <origin
        xyz="0.207914697106206 -0.000374618691388662 -0.0013446083065895"
        rpy="0 0 0" />
      <mass
        value="2.20888146035223" />
      <inertia
        ixx="0.0176750004221534"
        ixy="1.8058094778396E-07"
        ixz="-3.08108847310432E-06"
        iyy="0.0230757058106449"
        iyz="-1.32662462436481E-05"
        izz="0.0385405863901359" />
    </inertial>
    <visual>
      <origin
        xyz="0 0 0"
        rpy="0 0 0" />
      <geometry>
        <mesh
          filename="package://robot-description-irvin/meshes/right_outer_track_base_link.STL" />
      </geometry>
      <material
        name="">
        <color
          rgba="0.792156862745098 0.819607843137255 0.933333333333333 1" />
      </material>
    </visual>
    <collision>
      <origin
        xyz="0 0 0"
        rpy="0 0 0" />
      <geometry>
        <mesh
          filename="package://robot-description-irvin/meshes/right_outer_track_base_link.STL" />
      </geometry>
    </collision>
  </link>
  <joint
    name="right_outer_track_base_joint"
    type="fixed">
    <origin
      xyz="-0.38202 -0.061538 -0.0027053"
      rpy="1.5708 -0.0097345 0" />
    <parent
      link="right_outer_track_front_link" />
    <child
      link="right_outer_track_base_link" />
    <axis
      xyz="0 0 0" />
    <safety_controller
      k_velocity="0" />
  </joint>
  <link
    name="right_outer_rear_track_joint">
    <inertial>
      <origin
        xyz="-0.00205981876088107 -0.00999999113179895 -3.65024844378725E-08"
        rpy="0 0 0" />
      <mass
        value="4.50966940783013" />
      <inertia
        ixx="0.0357811712676883"
        ixy="6.29232664181182E-10"
        ixz="-2.48127828898167E-09"
        iyy="0.0215006200286184"
        iyz="-3.578694269125E-07"
        izz="0.0215020063072552" />
    </inertial>
    <visual>
      <origin
        xyz="0 0 0"
        rpy="0 0 0" />
      <geometry>
        <mesh
          filename="package://robot-description-irvin/meshes/right_outer_rear_track_joint.STL" />
      </geometry>
      <material
        name="">
        <color
          rgba="0.792156862745098 0.819607843137255 0.933333333333333 1" />
      </material>
    </visual>
    <collision>
      <origin
        xyz="0 0 0"
        rpy="0 0 0" />
      <geometry>
        <mesh
          filename="package://robot-description-irvin/meshes/right_outer_rear_track_joint.STL" />
      </geometry>
    </collision>
  </link>
  <joint
    name="right_outer_rear_track_joint"
    type="continuous">
    <origin
      xyz="0.033221 -0.010943 -0.0065379"
      rpy="3.0224 1.5708 0" />
    <parent
      link="right_outer_track_base_link" />
    <child
      link="right_outer_rear_track_joint" />
    <axis
      xyz="0 0 -1" />
    <safety_controller
      k_velocity="0" />
  </joint>
  <link
    name="torso_upper_link">
    <inertial>
      <origin
        xyz="9.37829586461492E-07 0.0377357679131104 0.00620378853168122"
        rpy="0 0 0" />
      <mass
        value="10.7560435121429" />
      <inertia
        ixx="0.126725000951128"
        ixy="5.37495458695421E-06"
        ixz="-1.6123169588652E-06"
        iyy="0.0655091626527598"
        iyz="0.000331778108296721"
        izz="0.155706969791532" />
    </inertial>
    <visual>
      <origin
        xyz="0 0 0"
        rpy="0 0 0" />
      <geometry>
        <mesh
          filename="package://robot-description-irvin/meshes/torso_upper_link.STL" />
      </geometry>
      <material
        name="">
        <color
          rgba="0.792156862745098 0.819607843137255 0.933333333333333 1" />
      </material>
    </visual>
    <collision>
      <origin
        xyz="0 0 0"
        rpy="0 0 0" />
      <geometry>
        <mesh
          filename="package://robot-description-irvin/meshes/torso_upper_link.STL" />
      </geometry>
    </collision>
  </link>
  <joint
    name="torso_upper_joint"
    type="fixed">
    <origin
      xyz="0.066422 -0.22881 0.63873"
      rpy="1.6088 0.001755 1.5247" />
    <parent
      link="base_link" />
    <child
      link="torso_upper_link" />
    <axis
      xyz="0 0 0" />
    <safety_controller
      k_velocity="0" />
  </joint>
</robot>