<?xml version="1.0"?>
<robot name="rhino">
  <gazebo>
    <plugin filename="libgazebo_ros_diff_drive.so" name="differential_drive_controller">
      <alwaysOn>true</alwaysOn>
      <updateRate>20</updateRate>
      <leftJoint>base_to_right_front_wheel</leftJoint>
      <rightJoint>base_to_left_front_wheel</rightJoint>
      <wheelSeparation>0.5207</wheelSeparation>
      <wheelDiameter>0.0762</wheelDiameter>
      <torque>0.1</torque>
      <commandTopic>cmd_vel</commandTopic>
      <odometryTopic>odom</odometryTopic>
      <odometryFrame>odom</odometryFrame>
      <robotBaseFrame>base_link</robotBaseFrame>
      <legacyMode>false</legacyMode>
    </plugin>
    <plugin filename="libgazebo_ros_diff_drive.so" name="differential_drive_controller">
      <alwaysOn>true</alwaysOn>
      <updateRate>20</updateRate>
      <leftJoint>base_to_right_rear_wheel</leftJoint>
      <rightJoint>base_to_left_rear_wheel</rightJoint>
      <wheelSeparation>0.5207</wheelSeparation>
      <wheelDiameter>0.0762</wheelDiameter>
      <torque>0.1</torque>
      <commandTopic>cmd_vel</commandTopic>
      <odometryTopic>odom</odometryTopic>
      <odometryFrame>odom</odometryFrame>
      <robotBaseFrame>base_link</robotBaseFrame>
      <legacyMode>false</legacyMode>
    </plugin>
  </gazebo>

  <material name="blue">
    <color rgba="0 0 0.8 1"/>
  </material>
  <material name="black">
    <color rgba="0 0 0 1"/>
  </material>
  <material name="white">
    <color rgba="1 1 1 1"/>
  </material>

  <link name="base_link">
    <inertial>
      <origin
        xyz="-0.0397613304580986 -0.00187447663786819 -0.0007976966428697"
        rpy="0 0 0" />
      <!-- <mass value="3.82068922610956" /> -->
      <mass value="10"/>
      <inertia
        ixx="0.280033582927332"
        ixy="-0.0109458890651764"
        ixz="-0.000139336718483203"
        iyy="0.441269583836676"
        iyz="9.2785508828341E-05"
        izz="0.185559829444659" />
    </inertial>
    <visual>
      <origin xyz="0 0 0.1" rpy="0 0 0"/>
      <geometry>
        <!-- <box size="0.3 0.3 0.1"/> -->
        <mesh filename="package://robot-description-rhino/meshes/base_link_new.STL"/>
      </geometry>
    </visual>
    <collision>
      <origin xyz="0 0 0.1" rpy="0 0 0"/>
<!-- 
      <geometry>
        <mesh
          filename="package://robot-description-rhino/meshes/base_link_new.STL" />
      </geometry>
      -->
      <geometry>
        <box size="0.8 0.7 0.2"/>
      </geometry> 
    </collision>
  </link>

  <!-- Torso Waist -->
  <link name="torso_waist">
    <visual>
      <origin rpy="0 0 0" xyz="0 0 0"/>
      <geometry>
        <cylinder length="0.1397" radius="0.05"/>
      </geometry>
    </visual>
    <collision>
      <origin rpy="0 0 0" xyz="0 0 0"/>
      <geometry>
        <cylinder length="0.5" radius="0.1"/>
      </geometry>
    </collision>
    <inertial>
      <mass value="5"/>
      <inertia ixx="0.4" ixy="0.0" ixz="0.0" iyy="0.4" iyz="0.0" izz="0.2"/>
    </inertial>
  </link>

  <joint name="base_to_torso_waist" type="revolute">
    <axis xyz="0 0 1"/>
    <origin xyz="0 0 0.16"/>
    <limit effort="1000.0" lower="-0.5" upper="0.5" velocity="0.5"/>
    <!-- <limit effort="100" velocity="100" /> -->
    <parent link="base_link"/>
    <child link="torso_waist"/>
  </joint>

  <!-- right_front_wheel with MESH-->
    <!--
  <link name="right_front_wheel">
    <inertial>
      <origin
        xyz="0.0403820397262787 -1.77100373879857E-08 -8.48161568756112E-09"
        rpy="0 0 0" />
      <mass value="0.168011919570301" />
      <inertia
        ixx="0.000126799359132551"
        ixy="4.2180094748375E-11"
        ixz="-9.55801614785873E-11"
        iyy="0.000112956774131014"
        iyz="2.87100617773173E-09"
        izz="0.000112951688012628" />
    </inertial>

    <visual>

      <geometry>
        <mesh filename="package://robot-description-rhino/meshes/right_front_wheel_link_new.STL"/>
      </geometry>
       <origin rpy="1.57075 0 0" xyz="0.064 0.30 0.060"/>
      <collision>
        <origin rpy="1.57075 0 0" xyz="0.064 0.30 0.060"/>
        <geometry>
          <mesh filename="package://robot-description-rhino/meshes/right_front_wheel_link_new.STL" />
        </geometry>
        <surface>
          <friction>
            <ode>
              <mu1>100.0</mu1>
              <mu2>50.0</mu2>
            </ode>
          </friction>
        </surface>
      </collision> 
    </visual>
  </link>
    -->

  <!-- right_front_wheel -->
  <link name="right_front_wheel">
    <inertial>
      <origin rpy="-1.57075 0 0" xyz="0 0 0"/>
      <mass value="0.168011919570301" />
      <inertia
        ixx="0.000126799359132551"
        ixy="4.2180094748375E-11"
        ixz="-9.55801614785873E-11"
        iyy="0.000112956774131014"
        iyz="2.87100617773173E-09"
        izz="0.000112951688012628" />
    </inertial>
    <visual>
      <origin rpy="-1.57075 0 0" xyz="0 0 0"/>
      <geometry>
        <cylinder length="0.05207" radius="0.05" />
      </geometry>
      <material name="white"/>
    </visual>
    <collision>
      <!-- <origin xyz="0 0 0" rpy="0 0 0" /> -->
      <origin rpy="-1.57075 0 0" xyz="0 0 0"/>
      <geometry>
        <cylinder length="0.05207" radius="0.05" />
      </geometry>
    </collision>
  </link>

  <joint name="base_to_right_front_wheel" type="continuous">
    <parent link="base_link"/>
    <child link="right_front_wheel"/>
    <origin xyz="0 -0.30 0.05"/>
    <axis xyz="0 1 0"/>
    <!-- <limit effort="100" velocity="100" /> -->
  </joint>


  <!-- 
    right rear wheel 
  -->
  <link name="right_rear_wheel">
    <inertial>
      <origin rpy="-1.57075 0 0" xyz="0 0 0"/>
      <mass value="0.172189485487845" />
      <inertia
        ixx="0.000122934028959951"
        ixy="-9.69198780790459E-11"
        ixz="8.40716510084883E-11"
        iyy="0.000135229835441607"
        iyz="-3.35713405092348E-10"
        izz="0.000122926656061839" />
    </inertial>
    <visual>
      <geometry>
        <cylinder length="0.05207" radius="0.05" />
      </geometry>
      <origin rpy="-1.57075 0 0" xyz="0 0 0"/>
      <material name="white"/>
    </visual>
    <collision>
      <origin rpy="-1.57075 0 0" xyz="0 0 0"/>
      <geometry>
        <cylinder length="0.05207" radius="0.05" />
      </geometry>
    </collision>
  </link>
  <joint name="base_to_right_rear_wheel" type="continuous">
    <parent link="base_link"/>
    <child link="right_rear_wheel"/>
    <origin xyz="-0.30 -0.30 0.05"/>
    <axis xyz="0 1 0"/>
    <!-- <limit effort="100" velocity="100" /> -->
  </joint>

  <!-- left front_wheel with MESH-->
  <!--
  <link name="left_front_wheel">
    <inertial>
      <origin
        xyz="0.040382041454872 1.76145017946605E-08 -8.69202679276704E-09"
        rpy="0 0 0" />
      <mass value="0.168011919570301" />
      <inertia
        ixx="0.000126799359132551"
        ixy="5.10665558282939E-11"
        ixz="9.11932344797647E-11"
        iyy="0.000112956782528061"
        iyz="-2.875306538123E-09"
        izz="0.000112951677864508" />
    </inertial>
    <visual>
    <geometry>
        <mesh filename="package://robot-description-rhino/meshes/left_front_wheel_link_new.STL"/>
      </geometry>
      <origin rpy="1.57075 0 0" xyz="0.064 -0.30 0.06"/> 
    <collision>
      <origin rpy="1.57075 0 0" xyz="0.064 -0.30 0.06"/>
      <geometry>
        <mesh filename="package://robot-description-rhino/meshes/left_front_wheel_link_new.STL" />
      </geometry>
      <surface>
        <friction>
          <ode>
            <mu1>100.0</mu1>
            <mu2>50.0</mu2>
          </ode>
        </friction>
      </surface>
    </collision> 
    </visual>
  </link>
    -->

  <link name="left_front_wheel">
    <inertial>
      <origin rpy="-1.57075 0 0" xyz="0 0 0"/>
      <mass value="0.168011919570301" />
      <inertia
        ixx="0.000126799359132551"
        ixy="5.10665558282939E-11"
        ixz="9.11932344797647E-11"
        iyy="0.000112956782528061"
        iyz="-2.875306538123E-09"
        izz="0.000112951677864508" />
    </inertial>
    <visual>
      <geometry>
          <cylinder length="0.05207" radius="0.05" />
      </geometry>
      <origin rpy="-1.57075 0 0" xyz="0 0 0"/>
      <material name="white"/>
    </visual>
    <collision>
      <!-- <origin xyz="0 0 0" rpy="0 0 0" /> -->
      <origin rpy="-1.57075 0 0" xyz="0 0 0"/>
      <geometry>
        <cylinder length="0.05207" radius="0.05" />
      </geometry>
    </collision>
  </link>

  <joint name="base_to_left_front_wheel" type="continuous">
    <parent link="base_link"/>
    <child link="left_front_wheel"/>
    <origin xyz="0 0.30 0.05"/>
    <axis xyz="0 1 0"/>
    <!-- <limit effort="100" velocity="100" /> -->
  </joint>


  <!-- Left Rear Wheel -->
  <link name="left_rear_wheel">
    <inertial>
      <origin rpy="-1.57075 0 0" xyz="0 0 0"/>
      <mass value="0.172189485243552" />
      <inertia
        ixx="0.000122934030023779"
        ixy="4.12976146803433E-10"
        ixz="-8.00350733438054E-10"
        iyy="0.000135229835425849"
        iyz="8.73155133668469E-12"
        izz="0.00012292611083972" />
    </inertial>
    <visual>
      <geometry>
          <cylinder length="0.05207" radius="0.05" />
      </geometry>
      <origin rpy="-1.57075 0 0" xyz="0 0 0"/>
      <material name="white"/>
    </visual>
    <collision>
      <!-- <origin xyz="0 0 0" rpy="0 0 0" /> -->
      <origin rpy="-1.57075 0 0" xyz="0 0 0"/>
      <geometry>
        <cylinder length="0.05207" radius="0.05"/>
      </geometry>
    </collision>
  </link>
  <joint name="base_to_left_rear_wheel" type="continuous">
    <parent link="base_link"/>
    <child link="left_rear_wheel"/>
    <origin xyz="-0.30 0.30 0.05"/>
    <axis xyz="0 1 0"/>
    <!-- <limit effort="100" velocity="100" /> -->
  </joint>

</robot>