<?xml version="1.0"?>
<!-- This URDF was automatically created by SolidWorks to URDF Exporter! Originally created by Stephen Brawner (brawner@gmail.com) 
     Commit Version: 1.5.0-0-g9aa0fdb  Build Version: 1.5.7004.21443
     For more information, please see http://wiki.ros.org/sw_urdf_exporter -->

<robot xmlns:sensor="http://playerstage.sourceforge.net/gazebo/xmlschema/#sensor"
  xmlns:controller="http://playerstage.sourceforge.net/gazebo/xmlschema/#controller"
  xmlns:interface="http://playerstage.sourceforge.net/gazebo/xmlschema/#interface"
  xmlns:xacro="http://www.ros.org/wiki/xacro"
  name="rhino">
<!--   <gazebo>
    <plugin filename="libgazebo_ros_diff_drive.so" name="differential_drive_controller">
      <alwaysOn>true</alwaysOn>
      <updateRate>20</updateRate>
      <leftJoint>l_front_gear_joint</leftJoint>
      <rightJoint>r_front_gear_joint</rightJoint>
      <wheelSeparation>0.5207</wheelSeparation>
      <wheelDiameter>0.0381</wheelDiameter>
      <torque>0.1</torque>
      <commandTopic>cmd_vel</commandTopic>
      <odometryTopic>odom</odometryTopic>
      <odometryFrame>odom</odometryFrame>
      <robotBaseFrame>base_link</robotBaseFrame>
    </plugin>
  </gazebo> -->
  <link
    name="base_link">
    <inertial>
      <origin
        xyz="-0.0854539444578278 -0.248510652272491 -0.0312116526849612"
        rpy="0 0 0" />
      <mass
        value="3.56295751873982" />
      <inertia
        ixx="0.257988964378837"
        ixy="-4.92926267539531E-05"
        ixz="0.00927576508424767"
        iyy="0.169815337004094"
        iyz="-0.000325135700747767"
        izz="0.404346652256536" />
    </inertial>
    <visual>
      <origin
        xyz="0 0 0"
        rpy="0 0 0" />
      <geometry>
        <mesh
          filename="package://robot-description-rhino/meshes/base_link.STL" />
      </geometry>
      <material
        name="">
        <color
          rgba="0.792156862745098 0.819607843137255 0.933333333333333 1" />
      </material>
    </visual>
    <collision>
      <origin
        xyz="0 0 0"
        rpy="0 0 0" />
      <geometry>
        <mesh
          filename="package://robot-description-rhino/meshes/base_link.STL" />
      </geometry>
    </collision>
  </link>
  <link
    name="r_front_gear_link">
    <inertial>
      <origin
        xyz="-1.7946086172671E-08 0.000932848402039943 -1.21516630091634E-10"
        rpy="0 0 0" />
      <mass
        value="0.159751645930498" />
      <inertia
        ixx="0.000101683067389321"
        ixy="-2.67439877595214E-12"
        ixz="-4.32552434761431E-14"
        iyy="0.000126695577433162"
        iyz="7.52063087514194E-11"
        izz="0.000101675353103401" />
    </inertial>
    <visual>
      <origin
        xyz="0 0 0"
        rpy="0 0 0" />
      <geometry>
        <mesh
          filename="package://robot-description-rhino/meshes/r_front_gear_link.STL" />
      </geometry>
      <material
        name="">
        <color
          rgba="0.792156862745098 0.819607843137255 0.933333333333333 1" />
      </material>
    </visual>
    <collision>
      <origin
        xyz="0 0 0"
        rpy="0 0 0" />
      <geometry>
        <cylinder radius="0.1" length="0.075"/>
      </geometry>
    </collision>
  </link>
  <joint
    name="r_front_gear_joint"
    type="continuous">
    <origin
      xyz="-0.302841769105532 0.0553113212582894 -0.085091106884355"
      rpy="-3.14159265358979 0.248289056196051 0" />
    <parent
      link="base_link" />
    <child
      link="r_front_gear_link" />
    <axis
      xyz="0 0 1" />
    <safety_controller
      k_velocity="0" />
  </joint>
  <link
    name="l_front_gear_link">
    <inertial>
      <origin
        xyz="-1.79460862281822E-08 0.00093284840204011 -1.21516602336058E-10"
        rpy="0 0 0" />
      <mass
        value="0.159751645930498" />
      <inertia
        ixx="0.000101683067389321"
        ixy="-2.67439883249513E-12"
        ixz="-4.32553806954293E-14"
        iyy="0.000126695577433162"
        iyz="7.52063087551771E-11"
        izz="0.000101675353103401" />
    </inertial>
    <visual>
      <origin
        xyz="0 0 0"
        rpy="0 0 0" />
      <geometry>
        <mesh
          filename="package://robot-description-rhino/meshes/l_front_gear_link.STL" />
      </geometry>
      <material
        name="">
        <color
          rgba="0.792156862745098 0.819607843137255 0.933333333333333 1" />
      </material>
    </visual>
    <collision>
      <origin
        xyz="0 0 0"
        rpy="0 0 0" />
      <geometry>
        <cylinder radius="0.1" length="0.075"/>
      </geometry>
    </collision>
  </link>
  <joint
    name="l_front_gear_joint"
    type="continuous">
    <origin
      xyz="-0.302841769105532 -0.552764678741711 -0.0850911068843571"
      rpy="-3.14159265358979 0.248289056196051 0" />
    <parent
      link="base_link" />
    <child
      link="l_front_gear_link" />
    <axis
      xyz="0 0 1" />
    <safety_controller
      k_velocity="0" />
  </joint>
  <link
    name="l_rear_gear_link">
    <inertial>
      <origin
        xyz="7.57477243706894E-08 -1.08693112843561E-08 0.0292794468265919"
        rpy="0 0 0" />
      <mass
        value="0.172189485209679" />
      <inertia
        ixx="0.000122932192302857"
        ixy="-3.43751007724576E-09"
        ixz="3.82354732243698E-10"
        iyy="0.000122927948516554"
        iyz="-1.56297480680647E-10"
        izz="0.000135229835419743" />
    </inertial>
    <visual>
      <origin
        xyz="0 0 0"
        rpy="0 0 0" />
      <geometry>
        <mesh
          filename="package://robot-description-rhino/meshes/l_rear_gear_link.STL" />
      </geometry>
      <material
        name="">
        <color
          rgba="0.792156862745098 0.819607843137255 0.933333333333333 1" />
      </material>
    </visual>
    <collision>
      <origin
        xyz="0 0 0"
        rpy="0 0 0" />
      <geometry>
        <cylinder radius="0.1" length="0.075"/>
      </geometry>
    </collision>
  </link>
  <joint
    name="l_rear_gear_joint"
    type="continuous">
    <origin
      xyz="0.154358230894468 -0.51955417874171 -0.0850911068843558"
      rpy="1.5707 0 0" />
    <parent
      link="base_link" />
    <child
      link="l_rear_gear_link" />
    <axis
      xyz="0 0 1" />
    <safety_controller
      k_velocity="0" />
  </joint>
  <link
    name="r_rear_gear_link">
    <inertial>
      <origin
        xyz="-4.28818209829984E-08 -7.9362040883435E-08 -0.0333434215720098"
        rpy="0 0 0" />
      <mass
        value="0.172189485469411" />
      <inertia
        ixx="0.000122932112918135"
        ixy="-3.23459466121525E-09"
        ixz="8.39145638229489E-11"
        iyy="0.000122928572079766"
        iyz="3.39198135872643E-10"
        izz="0.00013522983543829" />
    </inertial>
    <visual>
      <origin
        xyz="0 0 0"
        rpy="0 0 0" />
      <geometry>
        <mesh
          filename="package://robot-description-rhino/meshes/r_rear_gear_link.STL" />
      </geometry>
      <material
        name="">
        <color
          rgba="0.792156862745098 0.819607843137255 0.933333333333333 1" />
      </material>
    </visual>
    <collision>
      <origin
        xyz="0 0 0"
        rpy="0 0 0" />
      <geometry>
        <cylinder radius="0.1" length="0.075"/>
      </geometry>
    </collision>
  </link>
  <joint
    name="r_rear_gear_joint"
    type="continuous">
    <origin
      xyz="0.154358230894465 0.0180368212582895 -0.0850911068843606"
      rpy="1.5707 0 0" />
    <parent
      link="base_link" />
    <child
      link="r_rear_gear_link" />
    <axis
      xyz="0 0 1" />
    <safety_controller
      k_velocity="0" />
  </joint>

  <gazebo>
    <plugin name="skid_steer_drive_controller" filename="libgazebo_ros_skid_steer_drive.so">
      <updateRate>100.0</updateRate>
      <leftFrontJoint>l_front_gear_joint</leftFrontJoint>
      <rightFrontJoint>r_front_gear_joint</rightFrontJoint>
      <leftRearJoint>l_rear_gear_joint</leftRearJoint>
      <rightRearJoint>r_rear_gear_joint</rightRearJoint>
      <wheelSeparation>0.5207</wheelSeparation>
      <wheelDiameter>0.0762</wheelDiameter>
      <robotBaseFrame>base_link</robotBaseFrame>
      <torque>200</torque>
      <commandTopic>cmd_vel</commandTopic>
      <odometryTopic>odom</odometryTopic>
      <odometryFrame>odom</odometryFrame>
      <broadcastTF>true</broadcastTF>
    </plugin>
  </gazebo>

</robot>