<?xml version="1.0" encoding="utf-8"?>
<!-- This URDF was automatically created by SolidWorks to URDF Exporter! Originally created by Stephen Brawner (brawner@gmail.com) 
     Commit Version: 1.5.0-0-g9aa0fdb  Build Version: 1.5.7004.21443
     For more information, please see http://wiki.ros.org/sw_urdf_exporter -->
<robot
  name="robot-description-rhino">
  <link
    name="base_link">
    <inertial>
      <origin
        xyz="-0.0854539444578279 -0.248510652272491 -0.0312116526849612"
        rpy="0 0 0" />
      <mass
        value="3.56295751873982" />
      <inertia
        ixx="0.257988964378837"
        ixy="-4.92926267539462E-05"
        ixz="0.00927576508424767"
        iyy="0.169815337004094"
        iyz="-0.000325135700747762"
        izz="0.404346652256536" />
    </inertial>
    <visual>
      <origin
        xyz="0 0 0"
        rpy="0 0 0" />
      <geometry>
        <mesh
          filename="package://robot-description-rhino/meshes/base_link.STL" />
      </geometry>
      <material
        name="">
        <color
          rgba="0.792156862745098 0.819607843137255 0.933333333333333 1" />
      </material>
    </visual>
    <collision>
      <origin
        xyz="0 0 0"
        rpy="0 0 0" />
      <geometry>
        <mesh
          filename="package://robot-description-rhino/meshes/base_link.STL" />
      </geometry>
    </collision>
  </link>
  <link
    name="r_front_gear_link">
    <inertial>
      <origin
        xyz="-1.7946086172671E-08 0.000932848402039943 -1.21516630091634E-10"
        rpy="0 0 0" />
      <mass
        value="0.159751645930498" />
      <inertia
        ixx="0.000101683067389321"
        ixy="-2.67439877680263E-12"
        ixz="-4.32552400880113E-14"
        iyy="0.000126695577433162"
        iyz="7.52063087509797E-11"
        izz="0.000101675353103401" />
    </inertial>
    <visual>
      <origin
        xyz="0 0 0"
        rpy="0 0 0" />
      <geometry>
        <mesh
          filename="package://robot-description-rhino/meshes/r_front_gear_link.STL" />
      </geometry>
      <material
        name="">
        <color
          rgba="0.792156862745098 0.819607843137255 0.933333333333333 1" />
      </material>
    </visual>
    <collision>
      <origin
        xyz="0 0 0"
        rpy="0 0 0" />
      <geometry>
        <mesh
          filename="package://robot-description-rhino/meshes/r_front_gear_link.STL" />
      </geometry>
    </collision>
  </link>
  <joint
    name="r_front_gear_joint"
    type="continuous">
    <origin
      xyz="-0.30284 0.055311 -0.085091"
      rpy="-3.1416 0.24829 0" />
    <parent
      link="base_link" />
    <child
      link="r_front_gear_link" />
    <axis
      xyz="0 0 0" />
    <safety_controller
      k_velocity="0" />
  </joint>
  <link
    name="l_front_gear_link">
    <inertial>
      <origin
        xyz="-1.7946E-08 0.00093285 -1.2152E-10"
        rpy="0 0 0" />
      <mass
        value="0.15975" />
      <inertia
        ixx="0.00010168"
        ixy="-2.6744E-12"
        ixz="-4.3255E-14"
        iyy="0.0001267"
        iyz="7.5206E-11"
        izz="0.00010168" />
    </inertial>
    <visual>
      <origin
        xyz="0 0 0"
        rpy="0 0 0" />
      <geometry>
        <mesh
          filename="package://robot-description-rhino/meshes/l_front_gear_link.STL" />
      </geometry>
      <material
        name="">
        <color
          rgba="0.79216 0.81961 0.93333 1" />
      </material>
    </visual>
    <collision>
      <origin
        xyz="0 0 0"
        rpy="0 0 0" />
      <geometry>
        <mesh
          filename="package://robot-description-rhino/meshes/l_front_gear_link.STL" />
      </geometry>
    </collision>
  </link>
  <joint
    name="l_front_gear_joint"
    type="continuous">
    <origin
      xyz="-0.30284 -0.55276 -0.085091"
      rpy="0 0.24829 0" />
    <parent
      link="base_link" />
    <child
      link="l_front_gear_link" />
    <axis
      xyz="0 0 0" />
    <safety_controller
      k_velocity="0" />
  </joint>
  <link
    name="l_rear_gear_link">
    <inertial>
      <origin
        xyz="7.5748E-08 -1.0869E-08 0.029279"
        rpy="0 0 0" />
      <mass
        value="0.17219" />
      <inertia
        ixx="0.00012293"
        ixy="-3.4375E-09"
        ixz="3.8235E-10"
        iyy="0.00012293"
        iyz="-1.563E-10"
        izz="0.00013523" />
    </inertial>
    <visual>
      <origin
        xyz="0 0 0"
        rpy="0 0 0" />
      <geometry>
        <mesh
          filename="package://robot-description-rhino/meshes/l_rear_gear_link.STL" />
      </geometry>
      <material
        name="">
        <color
          rgba="0.79216 0.81961 0.93333 1" />
      </material>
    </visual>
    <collision>
      <origin
        xyz="0 0 0"
        rpy="0 0 0" />
      <geometry>
        <mesh
          filename="package://robot-description-rhino/meshes/l_rear_gear_link.STL" />
      </geometry>
    </collision>
  </link>
  <joint
    name="l_rear_gear_joint"
    type="continuous">
    <origin
      xyz="0.15436 -0.51955 -0.085091"
      rpy="1.5708 -0.56015 0" />
    <parent
      link="base_link" />
    <child
      link="l_rear_gear_link" />
    <axis
      xyz="0 0 0" />
    <safety_controller
      k_velocity="0" />
  </joint>
  <link
    name="r_rear_gear_link">
    <inertial>
      <origin
        xyz="0 0 0"
        rpy="0 0 0" />
      <mass
        value="0" />
      <inertia
        ixx="0"
        ixy="0"
        ixz="0"
        iyy="0"
        iyz="0"
        izz="0" />
    </inertial>
    <visual>
      <origin
        xyz="0 0 0"
        rpy="0 0 0" />
      <geometry>
        <mesh
          filename="package://robot-description-rhino/meshes/r_rear_gear_link.STL" />
      </geometry>
      <material
        name="">
        <color
          rgba="1 1 1 1" />
      </material>
    </visual>
    <collision>
      <origin
        xyz="0 0 0"
        rpy="0 0 0" />
      <geometry>
        <mesh
          filename="package://robot-description-rhino/meshes/r_rear_gear_link.STL" />
      </geometry>
    </collision>
  </link>
  <joint
    name="r_rear_gear_joint"
    type="continuous">
    <origin
      xyz="0.15436 0.018037 -0.085091"
      rpy="1.5708 -0.56015 0" />
    <parent
      link="base_link" />
    <child
      link="r_rear_gear_link" />
    <axis
      xyz="0 0 0" />
    <safety_controller
      k_velocity="0" />
  </joint>

  <!-- <gazebo>
    <plugin name="skid_steer_drive_controller" filename="libgazebo_ros_skid_steer_drive.so">
      <updateRate>100.0</updateRate>
      <!--robotNamespace>$(arg robot_name)</robotNamespace-->
      <leftFrontJoint>l_front_gear_joint</leftFrontJoint>
      <rightFrontJoint>r_front_gear_joint</rightFrontJoint>
      <leftRearJoint>l_rear_gear_joint</leftRearJoint>
      <rightRearJoint>r_rear_gear_joint</rightRearJoint>
      <wheelSeparation>0.4</wheelSeparation>
      <wheelDiameter>0.215</wheelDiameter>
      <robotBaseFrame>base_link</robotBaseFrame>
      <torque>200</torque>
      <commandTopic>cmd_vel</commandTopic>
      <odometryTopic>odom</odometryTopic>
      <odometryFrame>odom</odometryFrame>
      <broadcastTF>true</broadcastTF>
    </plugin>
  </gazebo> -->

</robot>